[2021-04-05 07:30:19,043] {taskinstance.py:826} INFO - Dependencies all met for <TaskInstance: baxa_lead_importer.main 2021-04-05T07:20:00+00:00 [queued]>
[2021-04-05 07:30:19,091] {taskinstance.py:826} INFO - Dependencies all met for <TaskInstance: baxa_lead_importer.main 2021-04-05T07:20:00+00:00 [queued]>
[2021-04-05 07:30:19,091] {taskinstance.py:1017} INFO - 
--------------------------------------------------------------------------------
[2021-04-05 07:30:19,091] {taskinstance.py:1018} INFO - Starting attempt 2 of 2
[2021-04-05 07:30:19,091] {taskinstance.py:1019} INFO - 
--------------------------------------------------------------------------------
[2021-04-05 07:30:19,113] {taskinstance.py:1038} INFO - Executing <Task(BashOperator): main> on 2021-04-05T07:20:00+00:00
[2021-04-05 07:30:19,120] {standard_task_runner.py:51} INFO - Started process 380048 to run task
[2021-04-05 07:30:19,131] {standard_task_runner.py:75} INFO - Running: ['airflow', 'tasks', 'run', 'baxa_lead_importer', 'main', '2021-04-05T07:20:00+00:00', '--job-id', '342', '--pool', 'default_pool', '--raw', '--subdir', 'DAGS_FOLDER/baxa_lead_importer.py', '--cfg-path', '/tmp/tmpua_6hiwg']
[2021-04-05 07:30:19,142] {standard_task_runner.py:76} INFO - Job 342: Subtask main
[2021-04-05 07:30:19,274] {logging_mixin.py:103} INFO - Running <TaskInstance: baxa_lead_importer.main 2021-04-05T07:20:00+00:00 [running]> on host airflowvm
[2021-04-05 07:30:19,397] {taskinstance.py:1230} INFO - Exporting the following env vars:
AIRFLOW_CTX_DAG_EMAIL=arun.padmanabhan00@gmail.com
AIRFLOW_CTX_DAG_OWNER=airflow
AIRFLOW_CTX_DAG_ID=baxa_lead_importer
AIRFLOW_CTX_TASK_ID=main
AIRFLOW_CTX_EXECUTION_DATE=2021-04-05T07:20:00+00:00
AIRFLOW_CTX_DAG_RUN_ID=scheduled__2021-04-05T07:20:00+00:00
[2021-04-05 07:30:19,398] {bash.py:135} INFO - Tmp dir root location: 
 /tmp
[2021-04-05 07:30:19,398] {bash.py:158} INFO - Running command: sleep 20
[2021-04-05 07:30:19,413] {bash.py:169} INFO - Output:
[2021-04-05 07:30:29,399] {timeout.py:36} ERROR - Process timed out, PID: 380048
[2021-04-05 07:30:29,399] {bash.py:185} INFO - Sending SIGTERM signal to bash process group
[2021-04-05 07:30:29,461] {taskinstance.py:1396} ERROR - Timeout, PID: 380048
Traceback (most recent call last):
  File "/home/airflow/venv/lib/python3.8/site-packages/airflow/models/taskinstance.py", line 1086, in _run_raw_task
    self._prepare_and_execute_task_with_callbacks(context, task)
  File "/home/airflow/venv/lib/python3.8/site-packages/airflow/models/taskinstance.py", line 1260, in _prepare_and_execute_task_with_callbacks
    result = self._execute_task(context, task_copy)
  File "/home/airflow/venv/lib/python3.8/site-packages/airflow/models/taskinstance.py", line 1295, in _execute_task
    result = task_copy.execute(context=context)
  File "/home/airflow/venv/lib/python3.8/site-packages/airflow/operators/bash.py", line 171, in execute
    for raw_line in iter(self.sub_process.stdout.readline, b''):
  File "/home/airflow/venv/lib/python3.8/site-packages/airflow/utils/timeout.py", line 37, in handle_timeout
    raise AirflowTaskTimeout(self.error_message)
airflow.exceptions.AirflowTaskTimeout: Timeout, PID: 380048
[2021-04-05 07:30:29,463] {taskinstance.py:1433} INFO - Marking task as FAILED. dag_id=baxa_lead_importer, task_id=main, execution_date=20210405T072000, start_date=20210405T073019, end_date=20210405T073029
[2021-04-05 07:30:29,564] {configuration.py:344} WARNING - section/key [smtp/smtp_user] not found in config
[2021-04-05 07:30:29,565] {email.py:184} INFO - Email alerting: attempt 1
[2021-04-05 07:30:29,587] {configuration.py:344} WARNING - section/key [smtp/smtp_user] not found in config
[2021-04-05 07:30:29,587] {email.py:184} INFO - Email alerting: attempt 1
[2021-04-05 07:30:29,588] {taskinstance.py:1446} ERROR - Failed to send email to: ['arun.padmanabhan00@gmail.com']
[2021-04-05 07:30:29,588] {taskinstance.py:1447} ERROR - [Errno 111] Connection refused
Traceback (most recent call last):
  File "/home/airflow/venv/lib/python3.8/site-packages/airflow/models/taskinstance.py", line 1086, in _run_raw_task
    self._prepare_and_execute_task_with_callbacks(context, task)
  File "/home/airflow/venv/lib/python3.8/site-packages/airflow/models/taskinstance.py", line 1260, in _prepare_and_execute_task_with_callbacks
    result = self._execute_task(context, task_copy)
  File "/home/airflow/venv/lib/python3.8/site-packages/airflow/models/taskinstance.py", line 1295, in _execute_task
    result = task_copy.execute(context=context)
  File "/home/airflow/venv/lib/python3.8/site-packages/airflow/operators/bash.py", line 171, in execute
    for raw_line in iter(self.sub_process.stdout.readline, b''):
  File "/home/airflow/venv/lib/python3.8/site-packages/airflow/utils/timeout.py", line 37, in handle_timeout
    raise AirflowTaskTimeout(self.error_message)
airflow.exceptions.AirflowTaskTimeout: Timeout, PID: 380048

During handling of the above exception, another exception occurred:

Traceback (most recent call last):
  File "/home/airflow/venv/lib/python3.8/site-packages/airflow/models/taskinstance.py", line 1786, in email_alert
    send_email(self.task.email, subject, html_content)
  File "/home/airflow/venv/lib/python3.8/site-packages/airflow/utils/email.py", line 52, in send_email
    return backend(
  File "/home/airflow/venv/lib/python3.8/site-packages/airflow/utils/email.py", line 97, in send_email_smtp
    send_mime_email(e_from=smtp_mail_from, e_to=recipients, mime_msg=msg, dryrun=dryrun)
  File "/home/airflow/venv/lib/python3.8/site-packages/airflow/utils/email.py", line 186, in send_mime_email
    conn = _get_smtp_connection(smtp_host, smtp_port, smtp_timeout, smtp_ssl)
  File "/home/airflow/venv/lib/python3.8/site-packages/airflow/utils/email.py", line 220, in _get_smtp_connection
    else smtplib.SMTP(host=host, port=port, timeout=timeout)
  File "/usr/lib/python3.8/smtplib.py", line 253, in __init__
    (code, msg) = self.connect(host, port)
  File "/usr/lib/python3.8/smtplib.py", line 339, in connect
    self.sock = self._get_socket(host, port, self.timeout)
  File "/usr/lib/python3.8/smtplib.py", line 308, in _get_socket
    return socket.create_connection((host, port), timeout,
  File "/usr/lib/python3.8/socket.py", line 808, in create_connection
    raise err
  File "/usr/lib/python3.8/socket.py", line 796, in create_connection
    sock.connect(sa)
ConnectionRefusedError: [Errno 111] Connection refused

During handling of the above exception, another exception occurred:

Traceback (most recent call last):
  File "/home/airflow/venv/lib/python3.8/site-packages/airflow/models/taskinstance.py", line 1444, in handle_failure
    self.email_alert(error)
  File "/home/airflow/venv/lib/python3.8/site-packages/airflow/models/taskinstance.py", line 1788, in email_alert
    send_email(self.task.email, subject, html_content_err)
  File "/home/airflow/venv/lib/python3.8/site-packages/airflow/utils/email.py", line 52, in send_email
    return backend(
  File "/home/airflow/venv/lib/python3.8/site-packages/airflow/utils/email.py", line 97, in send_email_smtp
    send_mime_email(e_from=smtp_mail_from, e_to=recipients, mime_msg=msg, dryrun=dryrun)
  File "/home/airflow/venv/lib/python3.8/site-packages/airflow/utils/email.py", line 186, in send_mime_email
    conn = _get_smtp_connection(smtp_host, smtp_port, smtp_timeout, smtp_ssl)
  File "/home/airflow/venv/lib/python3.8/site-packages/airflow/utils/email.py", line 220, in _get_smtp_connection
    else smtplib.SMTP(host=host, port=port, timeout=timeout)
  File "/usr/lib/python3.8/smtplib.py", line 253, in __init__
    (code, msg) = self.connect(host, port)
  File "/usr/lib/python3.8/smtplib.py", line 339, in connect
    self.sock = self._get_socket(host, port, self.timeout)
  File "/usr/lib/python3.8/smtplib.py", line 308, in _get_socket
    return socket.create_connection((host, port), timeout,
  File "/usr/lib/python3.8/socket.py", line 808, in create_connection
    raise err
  File "/usr/lib/python3.8/socket.py", line 796, in create_connection
    sock.connect(sa)
ConnectionRefusedError: [Errno 111] Connection refused
[2021-04-05 07:30:29,747] {local_task_job.py:118} INFO - Task exited with return code 1
