[2021-03-19 06:14:20,598] {taskinstance.py:826} INFO - Dependencies all met for <TaskInstance: parallel_dag.processing_tasks.bash2 2021-03-18T00:00:00+00:00 [queued]>
[2021-03-19 06:14:20,652] {taskinstance.py:826} INFO - Dependencies all met for <TaskInstance: parallel_dag.processing_tasks.bash2 2021-03-18T00:00:00+00:00 [queued]>
[2021-03-19 06:14:20,653] {taskinstance.py:1017} INFO - 
--------------------------------------------------------------------------------
[2021-03-19 06:14:20,653] {taskinstance.py:1018} INFO - Starting attempt 3 of 3
[2021-03-19 06:14:20,653] {taskinstance.py:1019} INFO - 
--------------------------------------------------------------------------------
[2021-03-19 06:14:20,696] {taskinstance.py:1038} INFO - Executing <Task(BashOperator): processing_tasks.bash2> on 2021-03-18T00:00:00+00:00
[2021-03-19 06:14:20,711] {standard_task_runner.py:75} INFO - Running: ['airflow', 'tasks', 'run', 'parallel_dag', 'processing_tasks.bash2', '2021-03-18T00:00:00+00:00', '--job-id', '165', '--pool', 'default_pool', '--raw', '--subdir', 'DAGS_FOLDER/parallel_dag.py', '--cfg-path', '/tmp/tmpjkg1yzz6']
[2021-03-19 06:14:20,712] {standard_task_runner.py:76} INFO - Job 165: Subtask processing_tasks.bash2
[2021-03-19 06:14:20,716] {standard_task_runner.py:51} INFO - Started process 25097 to run task
[2021-03-19 06:14:20,909] {logging_mixin.py:103} INFO - Running <TaskInstance: parallel_dag.processing_tasks.bash2 2021-03-18T00:00:00+00:00 [running]> on host airflowvm
[2021-03-19 06:14:21,013] {taskinstance.py:1396} ERROR - 'dict object' has no attribute 'my_param'
Traceback (most recent call last):
  File "/home/airflow/venv/lib/python3.8/site-packages/airflow/models/taskinstance.py", line 1086, in _run_raw_task
    self._prepare_and_execute_task_with_callbacks(context, task)
  File "/home/airflow/venv/lib/python3.8/site-packages/airflow/models/taskinstance.py", line 1224, in _prepare_and_execute_task_with_callbacks
    self.render_templates(context=context)
  File "/home/airflow/venv/lib/python3.8/site-packages/airflow/models/taskinstance.py", line 1684, in render_templates
    self.task.render_template_fields(context)
  File "/home/airflow/venv/lib/python3.8/site-packages/airflow/models/baseoperator.py", line 857, in render_template_fields
    self._do_render_template_fields(self, self.template_fields, context, jinja_env, set())
  File "/home/airflow/venv/lib/python3.8/site-packages/airflow/models/baseoperator.py", line 870, in _do_render_template_fields
    rendered_content = self.render_template(content, context, jinja_env, seen_oids)
  File "/home/airflow/venv/lib/python3.8/site-packages/airflow/models/baseoperator.py", line 907, in render_template
    return jinja_env.from_string(content).render(**context)
  File "/home/airflow/venv/lib/python3.8/site-packages/jinja2/environment.py", line 1090, in render
    self.environment.handle_exception()
  File "/home/airflow/venv/lib/python3.8/site-packages/jinja2/environment.py", line 832, in handle_exception
    reraise(*rewrite_traceback_stack(source=source))
  File "/home/airflow/venv/lib/python3.8/site-packages/jinja2/_compat.py", line 28, in reraise
    raise value.with_traceback(tb)
  File "<template>", line 5, in top-level template code
jinja2.exceptions.UndefinedError: 'dict object' has no attribute 'my_param'
[2021-03-19 06:14:21,029] {taskinstance.py:1433} INFO - Marking task as FAILED. dag_id=parallel_dag, task_id=processing_tasks.bash2, execution_date=20210318T000000, start_date=20210319T061420, end_date=20210319T061421
[2021-03-19 06:14:21,108] {local_task_job.py:118} INFO - Task exited with return code 1
