[2021-04-05 17:10:00,844] {taskinstance.py:826} INFO - Dependencies all met for <TaskInstance: baxa_lead_importer.main 2021-04-05T17:00:00+00:00 [queued]>
[2021-04-05 17:10:00,878] {taskinstance.py:826} INFO - Dependencies all met for <TaskInstance: baxa_lead_importer.main 2021-04-05T17:00:00+00:00 [queued]>
[2021-04-05 17:10:00,878] {taskinstance.py:1017} INFO - 
--------------------------------------------------------------------------------
[2021-04-05 17:10:00,878] {taskinstance.py:1018} INFO - Starting attempt 1 of 2
[2021-04-05 17:10:00,878] {taskinstance.py:1019} INFO - 
--------------------------------------------------------------------------------
[2021-04-05 17:10:00,919] {taskinstance.py:1038} INFO - Executing <Task(BashOperator): main> on 2021-04-05T17:00:00+00:00
[2021-04-05 17:10:00,927] {standard_task_runner.py:51} INFO - Started process 40279 to run task
[2021-04-05 17:10:00,947] {standard_task_runner.py:75} INFO - Running: ['airflow', 'tasks', 'run', 'baxa_lead_importer', 'main', '2021-04-05T17:00:00+00:00', '--job-id', '6', '--pool', 'default_pool', '--raw', '--subdir', 'DAGS_FOLDER/baxa_lead_importer.py', '--cfg-path', '/tmp/tmp0plh3kpc']
[2021-04-05 17:10:00,947] {standard_task_runner.py:76} INFO - Job 6: Subtask main
[2021-04-05 17:10:01,079] {logging_mixin.py:103} INFO - Running <TaskInstance: baxa_lead_importer.main 2021-04-05T17:00:00+00:00 [running]> on host airflowvm
[2021-04-05 17:10:01,198] {taskinstance.py:1230} INFO - Exporting the following env vars:
AIRFLOW_CTX_DAG_EMAIL=arun.padmanabhan00@gmail.com
AIRFLOW_CTX_DAG_OWNER=airflow
AIRFLOW_CTX_DAG_ID=baxa_lead_importer
AIRFLOW_CTX_TASK_ID=main
AIRFLOW_CTX_EXECUTION_DATE=2021-04-05T17:00:00+00:00
AIRFLOW_CTX_DAG_RUN_ID=scheduled__2021-04-05T17:00:00+00:00
[2021-04-05 17:10:01,198] {bash.py:135} INFO - Tmp dir root location: 
 /tmp
[2021-04-05 17:10:01,204] {bash.py:158} INFO - Running command: sleep 20
[2021-04-05 17:10:01,226] {bash.py:169} INFO - Output:
[2021-04-05 17:10:21,236] {bash.py:177} INFO - Command exited with return code 0
[2021-04-05 17:10:21,307] {taskinstance.py:1135} INFO - Marking task as SUCCESS. dag_id=baxa_lead_importer, task_id=main, execution_date=20210405T170000, start_date=20210405T171000, end_date=20210405T171021
[2021-04-05 17:10:21,394] {local_task_job.py:169} WARNING - State of this instance has been externally set to success. Terminating instance.
[2021-04-05 17:10:21,427] {process_utils.py:95} INFO - Sending Signals.SIGTERM to GPID 40279
[2021-04-05 17:10:21,464] {taskinstance.py:1214} ERROR - Received SIGTERM. Terminating subprocesses.
[2021-04-05 17:10:21,465] {bash.py:185} INFO - Sending SIGTERM signal to bash process group
[2021-04-05 17:10:21,465] {base.py:1371} ERROR - Error closing cursor
Traceback (most recent call last):
  File "/home/airflow/venv/lib/python3.8/site-packages/sqlalchemy/engine/base.py", line 1276, in _execute_context
    self.dialect.do_execute(
  File "/home/airflow/venv/lib/python3.8/site-packages/sqlalchemy/engine/default.py", line 593, in do_execute
    cursor.execute(statement, parameters)
  File "/home/airflow/venv/lib/python3.8/site-packages/MySQLdb/cursors.py", line 206, in execute
    res = self._query(query)
  File "/home/airflow/venv/lib/python3.8/site-packages/MySQLdb/cursors.py", line 319, in _query
    db.query(q)
  File "/home/airflow/venv/lib/python3.8/site-packages/MySQLdb/connections.py", line 259, in query
    _mysql.connection.query(self, query)
  File "/home/airflow/venv/lib/python3.8/site-packages/airflow/models/taskinstance.py", line 1215, in signal_handler
    task_copy.on_kill()
  File "/home/airflow/venv/lib/python3.8/site-packages/airflow/operators/bash.py", line 187, in on_kill
    os.killpg(os.getpgid(self.sub_process.pid), signal.SIGTERM)
ProcessLookupError: [Errno 3] No such process

During handling of the above exception, another exception occurred:

Traceback (most recent call last):
  File "/home/airflow/venv/lib/python3.8/site-packages/sqlalchemy/engine/base.py", line 1368, in _safe_close_cursor
    cursor.close()
  File "/home/airflow/venv/lib/python3.8/site-packages/MySQLdb/cursors.py", line 83, in close
    while self.nextset():
  File "/home/airflow/venv/lib/python3.8/site-packages/MySQLdb/cursors.py", line 137, in nextset
    nr = db.next_result()
MySQLdb._exceptions.ProgrammingError: (2014, "Commands out of sync; you can't run this command now")
[2021-04-05 17:10:21,503] {process_utils.py:61} INFO - Process psutil.Process(pid=40279, status='terminated', exitcode=1, started='17:10:00') (40279) terminated with exit code 1
[2021-04-05 17:10:21,503] {local_task_job.py:118} INFO - Task exited with return code 1
