[2021-03-11 05:01:37,770] {taskinstance.py:826} INFO - Dependencies all met for <TaskInstance: xcom_dag.task_4 2021-03-11T05:01:29.562393+00:00 [queued]>
[2021-03-11 05:01:37,836] {taskinstance.py:826} INFO - Dependencies all met for <TaskInstance: xcom_dag.task_4 2021-03-11T05:01:29.562393+00:00 [queued]>
[2021-03-11 05:01:37,836] {taskinstance.py:1017} INFO - 
--------------------------------------------------------------------------------
[2021-03-11 05:01:37,836] {taskinstance.py:1018} INFO - Starting attempt 1 of 1
[2021-03-11 05:01:37,836] {taskinstance.py:1019} INFO - 
--------------------------------------------------------------------------------
[2021-03-11 05:01:37,870] {taskinstance.py:1038} INFO - Executing <Task(PythonOperator): task_4> on 2021-03-11T05:01:29.562393+00:00
[2021-03-11 05:01:37,882] {standard_task_runner.py:51} INFO - Started process 136381 to run task
[2021-03-11 05:01:37,903] {standard_task_runner.py:75} INFO - Running: ['airflow', 'tasks', 'run', 'xcom_dag', 'task_4', '2021-03-11T05:01:29.562393+00:00', '--job-id', '113', '--pool', 'default_pool', '--raw', '--subdir', 'DAGS_FOLDER/xcom_dag.py', '--cfg-path', '/tmp/tmp6w1cfi4k']
[2021-03-11 05:01:37,914] {standard_task_runner.py:76} INFO - Job 113: Subtask task_4
[2021-03-11 05:01:38,021] {logging_mixin.py:103} INFO - Running <TaskInstance: xcom_dag.task_4 2021-03-11T05:01:29.562393+00:00 [running]> on host airflowvm
[2021-03-11 05:01:38,111] {taskinstance.py:1230} INFO - Exporting the following env vars:
AIRFLOW_CTX_DAG_OWNER=airflow
AIRFLOW_CTX_DAG_ID=xcom_dag
AIRFLOW_CTX_TASK_ID=task_4
AIRFLOW_CTX_EXECUTION_DATE=2021-03-11T05:01:29.562393+00:00
AIRFLOW_CTX_DAG_RUN_ID=manual__2021-03-11T05:01:29.562393+00:00
[2021-03-11 05:01:38,111] {logging_mixin.py:103} INFO - choose best model
[2021-03-11 05:01:38,111] {taskinstance.py:1396} ERROR - xcom_pull() got multiple values for argument 'task_ids'
Traceback (most recent call last):
  File "/home/airflow/venv/lib/python3.8/site-packages/airflow/models/taskinstance.py", line 1086, in _run_raw_task
    self._prepare_and_execute_task_with_callbacks(context, task)
  File "/home/airflow/venv/lib/python3.8/site-packages/airflow/models/taskinstance.py", line 1260, in _prepare_and_execute_task_with_callbacks
    result = self._execute_task(context, task_copy)
  File "/home/airflow/venv/lib/python3.8/site-packages/airflow/models/taskinstance.py", line 1300, in _execute_task
    result = task_copy.execute(context=context)
  File "/home/airflow/venv/lib/python3.8/site-packages/airflow/operators/python.py", line 117, in execute
    return_value = self.execute_callable()
  File "/home/airflow/venv/lib/python3.8/site-packages/airflow/operators/python.py", line 128, in execute_callable
    return self.python_callable(*self.op_args, **self.op_kwargs)
  File "/home/airflow/airflow/dags/xcom_dag.py", line 21, in _choose_best_model
    val=ti.xcom_pull('model_accuracy',task_ids=[
  File "/home/airflow/venv/lib/python3.8/site-packages/airflow/utils/session.py", line 65, in wrapper
    return func(*args, session=session, **kwargs)
TypeError: xcom_pull() got multiple values for argument 'task_ids'
[2021-03-11 05:01:38,114] {taskinstance.py:1433} INFO - Marking task as FAILED. dag_id=xcom_dag, task_id=task_4, execution_date=20210311T050129, start_date=20210311T050137, end_date=20210311T050138
[2021-03-11 05:01:38,165] {local_task_job.py:118} INFO - Task exited with return code 1
