[2021-03-30 07:59:46,644] {taskinstance.py:826} INFO - Dependencies all met for <TaskInstance: parallel_dag.processing_tasks.bash2 2021-03-28T00:00:00+00:00 [queued]>
[2021-03-30 07:59:46,716] {taskinstance.py:826} INFO - Dependencies all met for <TaskInstance: parallel_dag.processing_tasks.bash2 2021-03-28T00:00:00+00:00 [queued]>
[2021-03-30 07:59:46,716] {taskinstance.py:1017} INFO - 
--------------------------------------------------------------------------------
[2021-03-30 07:59:46,716] {taskinstance.py:1018} INFO - Starting attempt 4 of 4
[2021-03-30 07:59:46,716] {taskinstance.py:1019} INFO - 
--------------------------------------------------------------------------------
[2021-03-30 07:59:46,761] {taskinstance.py:1038} INFO - Executing <Task(BashOperator): processing_tasks.bash2> on 2021-03-28T00:00:00+00:00
[2021-03-30 07:59:46,763] {standard_task_runner.py:51} INFO - Started process 885969 to run task
[2021-03-30 07:59:46,806] {standard_task_runner.py:75} INFO - Running: ['airflow', 'tasks', 'run', 'parallel_dag', 'processing_tasks.bash2', '2021-03-28T00:00:00+00:00', '--job-id', '208', '--pool', 'default_pool', '--raw', '--subdir', 'DAGS_FOLDER/parallel_dag.py', '--cfg-path', '/tmp/tmp2lys9bs_']
[2021-03-30 07:59:46,806] {standard_task_runner.py:76} INFO - Job 208: Subtask processing_tasks.bash2
[2021-03-30 07:59:47,065] {logging_mixin.py:103} INFO - Running <TaskInstance: parallel_dag.processing_tasks.bash2 2021-03-28T00:00:00+00:00 [running]> on host airflowvm
[2021-03-30 07:59:47,330] {taskinstance.py:1230} INFO - Exporting the following env vars:
AIRFLOW_CTX_DAG_OWNER=airflow
AIRFLOW_CTX_DAG_ID=parallel_dag
AIRFLOW_CTX_TASK_ID=processing_tasks.bash2
AIRFLOW_CTX_EXECUTION_DATE=2021-03-28T00:00:00+00:00
AIRFLOW_CTX_DAG_RUN_ID=scheduled__2021-03-28T00:00:00+00:00
[2021-03-30 07:59:47,331] {bash.py:135} INFO - Tmp dir root location: 
 /tmp
[2021-03-30 07:59:47,331] {bash.py:158} INFO - Running command: 
cd /home/airflow/node
node app.js
[2021-03-30 07:59:47,354] {bash.py:169} INFO - Output:
[2021-03-30 07:59:49,451] {bash.py:173} INFO - Server running at http://127.0.0.1:3000/
[2021-03-30 08:00:32,845] {local_task_job.py:169} WARNING - State of this instance has been externally set to shutdown. Terminating instance.
[2021-03-30 08:00:32,890] {process_utils.py:95} INFO - Sending Signals.SIGTERM to GPID 885969
[2021-03-30 08:00:32,890] {taskinstance.py:1214} ERROR - Received SIGTERM. Terminating subprocesses.
[2021-03-30 08:00:32,891] {bash.py:185} INFO - Sending SIGTERM signal to bash process group
[2021-03-30 08:00:32,939] {taskinstance.py:1396} ERROR - Task received SIGTERM signal
Traceback (most recent call last):
  File "/home/airflow/venv/lib/python3.8/site-packages/airflow/models/taskinstance.py", line 1086, in _run_raw_task
    self._prepare_and_execute_task_with_callbacks(context, task)
  File "/home/airflow/venv/lib/python3.8/site-packages/airflow/models/taskinstance.py", line 1260, in _prepare_and_execute_task_with_callbacks
    result = self._execute_task(context, task_copy)
  File "/home/airflow/venv/lib/python3.8/site-packages/airflow/models/taskinstance.py", line 1300, in _execute_task
    result = task_copy.execute(context=context)
  File "/home/airflow/venv/lib/python3.8/site-packages/airflow/operators/bash.py", line 171, in execute
    for raw_line in iter(self.sub_process.stdout.readline, b''):
  File "/home/airflow/venv/lib/python3.8/site-packages/airflow/models/taskinstance.py", line 1216, in signal_handler
    raise AirflowException("Task received SIGTERM signal")
airflow.exceptions.AirflowException: Task received SIGTERM signal
[2021-03-30 08:00:32,941] {taskinstance.py:1433} INFO - Marking task as FAILED. dag_id=parallel_dag, task_id=processing_tasks.bash2, execution_date=20210328T000000, start_date=20210330T075946, end_date=20210330T080032
[2021-03-30 08:00:33,050] {process_utils.py:61} INFO - Process psutil.Process(pid=885999, status='terminated', started='07:59:46') (885999) terminated with exit code None
[2021-03-30 08:00:33,050] {process_utils.py:61} INFO - Process psutil.Process(pid=885969, status='terminated', exitcode=1, started='07:59:46') (885969) terminated with exit code 1
[2021-03-30 08:00:33,051] {local_task_job.py:118} INFO - Task exited with return code 1
